<?xml version="1.0"?>
<robot name="mrp1">
  <link name="base_footprint">
      <origin xyz="0 0 0.0" rpy="0 0 1.57079633" />
      <inertial>
        <mass value="0.0001" />
        <origin xyz="0 0 0" />
        <inertia ixx="0.0001" ixy="0.0" ixz="0.0"
                 iyy="0.0001" iyz="0.0" 
                 izz="0.0001" />
      </inertial>
      <visual>
        <origin xyz="0 0 0.0" rpy="0 0 1.57079633" />
        <geometry>
          <box size="0.001 0.001 0.001" />
        </geometry>
      </visual>
      
      <collision>
        <origin xyz="0 0 0.0" rpy="0 0 1.57079633" />
        <geometry>
          <box size="0.001 0.001 0.001" />
        </geometry>
      </collision>
  </link>
    
  <link name="base_link">
    <inertial>
        <mass value="10" />
        <origin xyz="0 0 0" />
        <inertia ixx="0.10" ixy="0.0" ixz="0.0"
                 iyy="0.10" iyz="0.0" 
                 izz="0.10" />
    </inertial>
    <visual>
        <origin xyz="0 0 0" rpy="0 0 0" />
        <geometry>
              <mesh filename="package://mrp1_description/meshes/chassis-suspension.dae" />
          </geometry>
      </visual>
      <collision>
          <origin xyz="0 0 0" rpy="0 0 0" />
          <geometry>
              <mesh filename="package://mrp1_description/meshes/chassis-suspension.dae" />
          </geometry>
      </collision>
  </link>
  
  <joint name="base_footprint_joint" type="fixed">
      <origin xyz="0 0 0.0" rpy="0 0 1.57079633" />
      <parent link="base_footprint"/>
      <child link="base_link" />
  </joint>  
  
  <link name="front_right_wheel_link">
    <inertial>
        <mass value="1" />
        <origin xyz="0 0 0" />
        <inertia  ixx="0.012411765597" ixy="0.0" ixz="0.0"
                  iyy="0.015218160428" iyz="0.0"
                  izz="0.011763977943" />
    </inertial>
    <visual>
        <origin xyz="0 0 0" rpy="0 0 0" />
        <geometry>
            <mesh filename="package://mrp1_description/meshes/wheel.dae"/>
        </geometry>
    </visual>
    <collision>
        <origin xyz="0 0 0" rpy="0 0 0" />
        <geometry>                                      
            <mesh filename="package://mrp1_description/meshes/wheel.dae"/>
        </geometry>
    </collision>
  </link>
  <link name="front_left_wheel_link">
    <inertial>
        <mass value="1" />
        <origin xyz="0 0 0" rpy="0 0 3.14159265" />
        <inertia  ixx="0.012411765597" ixy="0.0" ixz="0.0"
                  iyy="0.015218160428" iyz="0.0"
                  izz="0.011763977943" />
    </inertial>
    <visual>
        <origin xyz="0 0 0" rpy="0 0 3.14159265" />
        <geometry>
            <mesh filename="package://mrp1_description/meshes/wheel.dae"/>
        </geometry>
    </visual>
    <collision>
        <origin xyz="0 0 0" rpy="0 0 3.14159265"/>
        <geometry>                                      
            <mesh filename="package://mrp1_description/meshes/wheel.dae"/>
        </geometry>
    </collision>
  </link>
  
<link name="rear_right_wheel_link">
    <inertial>
        <mass value="1" />
        <origin xyz="0 0 0" />
        <inertia  ixx="0.012411765597" ixy="0.0" ixz="0.0"
                  iyy="0.015218160428" iyz="0.0"
                  izz="0.011763977943" />
    </inertial>
    <visual>
        <origin xyz="0 0 0" rpy="0 0 0" />
        <geometry>
            <mesh filename="package://mrp1_description/meshes/wheel.dae"/>
        </geometry>
    </visual>
    <collision>
        <origin xyz="0 0 0" rpy="0 0 0" />
        <geometry>                                      
            <mesh filename="package://mrp1_description/meshes/wheel.dae"/>
        </geometry>
    </collision>
  </link>

  <link name="rear_left_wheel_link">
    <inertial>
        <mass value="1" />
        <origin xyz="0 0 0" />
        <inertia  ixx="0.012411765597" ixy="0.0" ixz="0.0"
                  iyy="0.015218160428" iyz="0.0"
                  izz="0.011763977943" />
    </inertial>
    <visual>
        <origin xyz="0 0 0" rpy="0 0 3.14159265" />
        <geometry>
            <mesh filename="package://mrp1_description/meshes/wheel.dae"/>
        </geometry>
    </visual>
    <collision>
        <origin xyz="0 0 0" rpy="0 0 3.14159265" />
        <geometry>                                      
            <mesh filename="package://mrp1_description/meshes/wheel.dae"/>
        </geometry>
    </collision>
  </link>
  
  <joint name="front_right_wheel_joint" type="continuous">
    <axis xyz="1 0 0" />
    <anchor xyz="0 0 0" />
    <limit effort="100" velocity="200" />
    <joint_properties damping="0.0" friction="0.0" />
    <parent link="base_link" />
    <child link="front_right_wheel_link" />
    <origin xyz="0.515 0.3850 -0.230" rpy="0 0 0" />
  </joint>
    
  <joint name="front_left_wheel_joint" type="continuous">
    <axis xyz="1 0 0" />
    <anchor xyz="0 0 0" />
    <limit effort="100" velocity="200" />
    <joint_properties damping="0.0" friction="0.0" />
    <parent link="base_link" />
    <child link="front_left_wheel_link" />
    <origin xyz="-0.4800 0.3850 -0.230" rpy="0 0 0" />
  </joint>  
    <joint name="rear_right_wheel_joint" type="continuous">
    <axis xyz="1 0 0" />
    <anchor xyz="0 0 0" />
    <limit effort="100" velocity="200" />
    <joint_properties damping="0.0" friction="0.0" />
    <parent link="base_link" />
    <child link="rear_right_wheel_link" />
    <origin xyz="0.515 -0.3850 -0.230" rpy="0 0 0" />
  
  </joint>
    <joint name="rear_left_wheel_joint" type="continuous">
    <axis xyz="1 0 0" />
    <anchor xyz="0 0 0" />
    <limit effort="100" velocity="200" />
    <joint_properties damping="0.0" friction="0.0" />
    <parent link="base_link" />
    <child link="rear_left_wheel_link" />
    <origin xyz="-0.4800 -0.3850 -0.230" rpy="0 0 0" />
  </joint>
  
</robot>
